<mujoco model="jaco_v2">
    <actuator>
        <!-- Physical limits of the actuator. Pulled from raw actuator spec sheet, see:
         https://www.kinovarobotics.com/sites/default/files/AS-ACT-KA58-KA75-SP-INT-EN%20201804-1.2%20%28KINOVA%E2%84%A2%20Actuator%20series%20KA75%2B%20KA-58%20Specifications%29.pdf -->
        <motor ctrllimited="true" ctrlrange="-30.5 30.5" joint="j2s7s300_joint_1" name="torq_j1"/>
        <motor ctrllimited="true" ctrlrange="-30.5 30.5" joint="j2s7s300_joint_2" name="torq_j2"/>
        <motor ctrllimited="true" ctrlrange="-30.5 30.5" joint="j2s7s300_joint_3" name="torq_j3"/>
        <motor ctrllimited="true" ctrlrange="-30.5 30.5" joint="j2s7s300_joint_4" name="torq_j4"/>
        <motor ctrllimited="true" ctrlrange="-30.5 30.5" joint="j2s7s300_joint_5" name="torq_j5"/>
        <motor ctrllimited="true" ctrlrange="-6.8 6.8" joint="j2s7s300_joint_6" name="torq_j6"/>
        <motor ctrllimited="true" ctrlrange="-6.8 6.8" joint="j2s7s300_joint_7" name="torq_j7"/>
        <position name='thumb' ctrllimited="true" kp="20" joint='joint_thumb' ctrlrange='0 1.51' forcelimited="true" forcerange="-0.3 0.3" />
        <position name='index' ctrllimited="true" kp="20" joint='joint_index' ctrlrange='0 1.51' forcelimited="true" forcerange="-0.3 0.3" />
        <position name='pinky'  ctrllimited="true" kp="20" joint='joint_pinky' ctrlrange='0 1.51' forcelimited="true" forcerange="-0.3 0.3" />
    </actuator>
    <asset>
        <mesh file="common_meshes/pedestal.stl" name="pedestal"/>
        <mesh name="base" file="meshes/base.stl" />
        <mesh name="shoulder" file="meshes/shoulder.stl" />
        <mesh name="ring_big" file="meshes/ring_big.stl" />
        <mesh name="arm_half_1" file="meshes/arm_half_1.stl" />
        <mesh name="arm_half_2" file="meshes/arm_half_2.stl" />
        <mesh name="forearm" file="meshes/forearm.stl" />
        <mesh name="ring_small" file="meshes/ring_small.stl" />
        <mesh name="wrist_spherical_1" file="meshes/wrist_spherical_1.stl" />
        <mesh name="wrist_spherical_2" file="meshes/wrist_spherical_2.stl" />

        <!-- Custom textures based on body names for domain randomization -->
        <texture type="cube" name="pedestal_tex" builtin="flat" width="100" height="100" rgb1="0.2 0.2 0.2" rgb2="0.2 0.2 0.2"/>

        <!-- Custom mats based on body names for domain randomization -->
        <material name="pedestal_mat" texture="pedestal_tex"/>

        <!-- Materials for robot -->
        <material name="carbon_jaco" specular="1" shininess="1" reflectance="1" rgba="0.05 0.05 0.05 1" emission="1" />
        <material name="grey_plastic_jaco" specular="0.5" shininess="0" reflectance="0" rgba="0.12 0.14 0.14 1" emission="1" />

        <!-- Gripper assets -->
        <mesh name="hand_3finger" file="meshes/jaco_three_finger_gripper/hand_3finger.stl" />
        <mesh name="finger_proximal" file="meshes/jaco_three_finger_gripper/finger_proximal.stl" />
        <mesh name="finger_distal" file="meshes/jaco_three_finger_gripper/finger_distal.stl" />
        <mesh name="ring_small_gripper" file="meshes/jaco_three_finger_gripper/ring_small.stl" />
        <!-- Materials for hand -->
        <material name="carbon_hand" specular="1" shininess="1" reflectance="1" rgba="0.05 0.05 0.05 1" emission="1" />
        <material name="grey_plastic_hand" specular="0.5" shininess="0" reflectance="0" rgba="0.12 0.14 0.14 1" emission="1" />
    </asset>
    <worldbody>
        <body name="base" pos="0 0 0">

            <!-- robot view -->
            <camera mode="fixed" name="robotview" pos="1.0 0 0.4" quat="0.653 0.271 0.271 0.653"/>
            <inertial diaginertia="0 0 0" mass="0" pos="0 0 0"/>
            <body name="controller_box" pos="0 0 0">
                <inertial diaginertia="1.71363 1.27988 0.809981" mass="46.64" pos="-0.325 0 -0.38"/>
                <geom pos="-0.325 0 -0.38" size="0.11 0.2 0.265" type="box" name="controller_box_col"/>
            </body>
            <body name="pedestal_feet" pos="0 0 0">
                <inertial diaginertia="8.16095 9.59375 15.0785" mass="167.09" pos="-0.1225 0 -0.758"/>
                <geom pos="-0.1225 0 -0.758" size="0.385 0.35 0.155" type="box" name="pedestal_feet_col"/>
            </body>
            <body name="torso" pos="0 0 0">
                <inertial diaginertia="1e-08 1e-08 1e-08" mass="0.0001" pos="0 0 0"/>
                <geom conaffinity="0" contype="0" group="1" rgba="0.2 0.2 0.2 1" size="0.05 0.05 0.05" type="box" name="torso_col"/>
            </body>
            <body name="pedestal" pos="0 0 0">
                <inertial diaginertia="6.0869 5.81635 4.20915" mass="60.864" pos="0 0 0" quat="0.659267 -0.259505 -0.260945 0.655692"/>
                <geom conaffinity="0" contype="0" group="1" mesh="pedestal" type="mesh" name="pedestal_col1" material="pedestal_mat" />
                <geom pos="-0.02 0 -0.29" rgba="0.2 0.2 0.2 1" size="0.18 0.31" type="cylinder" name="pedestal_col2"/>
            </body>
            <!--<inertial pos="0 0 0.05" mass="4" diaginertia="0.4 0.4 0.4" />-->
            <geom type="mesh" contype="0" conaffinity="0" group="1" material="carbon_jaco" mesh="base" />
            <geom type="mesh" material="carbon_jaco" mesh="base" />
            <body name="j2s7s300_link_1" pos="0 0 0.15675" quat="0 0 1 0">
                <inertial pos="0 -0.002 -0.0605" mass="0.7477" diaginertia="0.00152032 0.00152032 0.00059816" />
                <joint name="j2s7s300_joint_1" pos="0 0 0" axis="0 0 1" limited="true" range="-6.28319 6.28319" damping="0.1" frictionloss="0.01"/>
                <geom type="mesh" contype="0" conaffinity="0" group="1" material="carbon_jaco" mesh="shoulder" />
                <geom type="mesh" contype="0" conaffinity="0" group="1" material="grey_plastic_jaco" mesh="ring_big" />
                <geom type="mesh" material="carbon_jaco" mesh="shoulder" name="s_collision"/>
                <body name="j2s7s300_link_2" pos="0 0.0016 -0.11875" quat="0 0 -0.707107 0.707107">
                    <inertial pos="0 -0.103563 0" quat="0.707107 0.707107 0 0" mass="0.8447" diaginertia="0.00247074 0.00247074 0.000380115" />
                    <joint name="j2s7s300_joint_2" pos="0 0 0" axis="0 0 1" limited="true" range="0.820305 5.46288" damping="0.1" frictionloss="0.01"/>
                    <geom type="mesh" contype="0" conaffinity="0" group="1" material="carbon_jaco" mesh="arm_half_1" />
                    <geom type="mesh" contype="0" conaffinity="0" group="1" material="grey_plastic_jaco" mesh="ring_big" />
                    <geom type="mesh" material="carbon_jaco" mesh="arm_half_1" name="ah1_collision"/>
                    <body name="j2s7s300_link_3" pos="0 -0.205 0" quat="0.707107 -0.707107 0 0">
                        <inertial pos="0 0 -0.102245" mass="0.8447" diaginertia="0.00247074 0.00247074 0.000380115" />
                        <joint name="j2s7s300_joint_3" pos="0 0 0" axis="0 0 1" limited="true" range="-6.28319 6.28319" damping="0.1" frictionloss="0.01"/>
                        <geom type="mesh" contype="0" conaffinity="0" group="1" material="carbon_jaco" mesh="arm_half_2" />
                        <geom type="mesh" contype="0" conaffinity="0" group="1" material="grey_plastic_jaco" mesh="ring_big" />
                        <geom type="mesh" material="carbon_jaco" mesh="arm_half_2" name="ah2_collision"/>
                        <body name="j2s7s300_link_4" pos="0 0 -0.205" quat="0 0 0.707107 0.707107">
                            <inertial pos="0 0.081 -0.0086" quat="0.707107 0.707107 0 0" mass="0.6763" diaginertia="0.00142022 0.00142022 0.000304335" />
                            <joint name="j2s7s300_joint_4" pos="0 0 0" axis="0 0 1" limited="true" range="0.523599 5.75959" damping="0.1" frictionloss="0.01"/>
                            <geom type="mesh" contype="0" conaffinity="0" group="1" material="carbon_jaco" mesh="forearm" />
                            <geom type="mesh" contype="0" conaffinity="0" group="1" material="grey_plastic_jaco" mesh="ring_small" />
                            <geom type="mesh" material="carbon_jaco" mesh="forearm" name="f_collision"/>
                            <body name="j2s7s300_link_5" pos="0 0.2073 -0.0114" quat="0 0 -0.707107 0.707107">
                                <inertial pos="0 0.00288489 -0.0541933" mass="0.463" diaginertia="0.000432132 0.000432132 9.26e-05" />
                                <joint name="j2s7s300_joint_5" pos="0 0 0" axis="0 0 1" limited="true" range="-6.28319 6.28319" damping="0.1" frictionloss="0.01"/>
                                <geom type="mesh" contype="0" conaffinity="0" group="1" material="carbon_jaco" mesh="wrist_spherical_1" />
                                <geom type="mesh" contype="0" conaffinity="0" group="1" material="grey_plastic_jaco" mesh="ring_small" />
                                <geom type="mesh" material="carbon_jaco" mesh="wrist_spherical_1" name="ws1_collision"/>
                                <body name="j2s7s300_link_6" pos="0 0 -0.10375" quat="0 0 0.707107 0.707107">
                                    <inertial pos="0 0.0497209 -0.00285628" quat="0.707107 0.707107 0 0" mass="0.463" diaginertia="0.000432132 0.000432132 9.26e-05" />
                                    <joint name="j2s7s300_joint_6" pos="0 0 0" axis="0 0 1" limited="true" range="1.13446 5.14872" damping="0.01" frictionloss="0.01"/>
                                    <geom type="mesh" contype="0" conaffinity="0" group="1" material="carbon_jaco" mesh="wrist_spherical_2" />
                                    <geom type="mesh" contype="0" conaffinity="0" group="1" material="grey_plastic_jaco" mesh="ring_small" />
                                    <geom type="mesh" material="carbon_jaco" mesh="wrist_spherical_2" name="ws2_collision"/>
                                    <body name="j2s7s300_link_7" pos="0 0.10375 0" quat="0 0 -0.707107 0.707107">
                                        <inertial pos="0 0 -0.06" quat="0.5 0.5 -0.5 0.5" mass="1e-6" diaginertia="1e-6 1e-6 1e-6" /> <!--mass="0.99" diaginertia="0.0005816 0.000345324 0.000345324" /> -->
                                        <joint name="j2s7s300_joint_7" pos="0 0 0" axis="0 0 1" limited="true" range="-6.28319 6.28319" damping="0.01" frictionloss="0.01"/>
                                        <body name="right_hand" pos="0 0 0" quat="0 1 0 0">
                                            <!-- This sites were added for visualization. They are all standardized between models-->
                                            <!-- Position mimics the gripper attachment point (right_hand) -->
                                            <!--  Y-axis should be perpendicular to grasping motion, and Z-axis should point out of the robot eef -->
                                            <site name="ee" pos="0 0 0" size="0.01 0.01 0.01" rgba="0 0 1 1" type="sphere" group="1"/>
                                            <site name="ee_x" pos="0 0 0" size="0.005 .1"  quat="0.707105 0.707108 0 0 " rgba="1 0 0 0" type="cylinder" group="1"/>
                                            <site name="ee_z" pos="0 0 0" size="0.005 .1" quat="0.707105 0 0 0.707108" rgba="0 0 1 0" type="cylinder" group="1"/>
                                            <site name="ee_y" pos="0 0 0" size="0.005 .1" quat="0.707105 0 0.707108 0 " rgba="0 1 0 0" type="cylinder" group="1"/>
                                            <!-- This camera points out from the eef. -->
                                            <camera mode="fixed" name="eye_in_hand" pos="0.08 0 0" quat="0 0.707108 0.707108 0" fovy="75"/>
                                            <!-- To add gripper -->
                                            <!-- Note: This model is a tendon-driven variation of the model found at https://github.com/abr/abr_control/blob/master/abr_control/arms/jaco2/jaco2.xml -->
                                            <body name="right_gripper" pos="0 0 0">
                                                <inertial pos="0 0 0" mass="1e-6" diaginertia="1e-08 1e-08 1e-08" />
                                                <body name="palm" pos="0 0 0" quat="0 -1 0 0">
                                                    <inertial pos="0 0 -0.06" quat="0.5 0.5 -0.5 0.5" mass="0.99" diaginertia="0.0005816 0.000345324 0.000345324" />
                                                    <geom type="mesh" contype="0" conaffinity="0" group="1" material="carbon_hand" mesh="hand_3finger" />
                                                    <geom type="mesh" contype="0" conaffinity="0" group="1" material="grey_plastic_hand" mesh="ring_small_gripper" />
                                                    <geom type="mesh" material="carbon_hand" mesh="hand_3finger" name="hand_collision"/>

                                                    <site name="ft_frame" pos="0 0 0" size="0.01 0.01 0.01" rgba="1 0 0 1" type="sphere" group="1" />

                                                    <!-- This site was added for visualization. -->
                                                    <site name="grip_site" pos="0 0 -0.1775" size="0.01 0.01 0.01" rgba="1 0 0 1" type="sphere" group="1"/>
                                                    <!-- This site was added for visualization. -->
                                                    <site name="grip_site_cylinder" pos="0 0 0.1399" size="0.005 10" rgba="0 1 0 0.3" type="cylinder" group="1"/>
                                                </body>

                                                <body name="thumb_proximal" pos="0.002786 -0.03126 0.114668" quat="0.95922726  0.262085 0.02762996 -0.10213274">
                                                    <inertial pos="0.022 0 0" mass="0.01" diaginertia="7.89997e-07 7.89997e-07 8e-08" />
                                                    <joint name="joint_thumb" pos="0 0 0" axis="1 0 0" ref="1.1" limited="true" range="0 1.51" damping="0.15"/>
                                                    <geom type="mesh" contype="0" conaffinity="0" group="1" euler="0 -1.5707 0" material="grey_plastic_hand" mesh="finger_proximal" />
                                                    <geom name="thumb_proximal_collision" type="mesh" mesh="finger_proximal" euler="0 -1.5707 0" friction="1 0.5 0.01" />

                                                    <body name="thumb_distal" pos="0 -0.003 0.044">
                                                        <inertial pos="0.022 0 0" mass="0.01" diaginertia="7.89997e-07 7.89997e-07 8e-08" />
                                                        <joint name="joint_thumb_distal" pos="0 0 0" axis="-1 0 0" ref="-0.5" limited="true" range="0 2" damping="0.1" />
                                                        <geom type="mesh" contype="0" conaffinity="0" group="1" euler="0 -1.5707 0" material="grey_plastic_hand" mesh="finger_distal" />
                                                        <geom name="thumb_distal_collision" type="mesh" mesh="finger_distal" euler="0 -1.5707 0" friction="1 0.5 0.01" />
                                                        <geom type="box" pos="0 -0.003 0.021" quat="0.9914449 0.1305262 0 0" size="0.01 0.005 0.02" name="thumb_pad_collision" solref="0.01 0.25" friction="2 0.05 0.001" />
                                                    </body>
                                                </body>

                                                <body name="index_proximal" pos="0.022256 0.027073 0.114668" quat="0.96181018 -0.25771638 0.0238668 -0.08907205">
                                                    <inertial pos="0.022 0 0" mass="0.01" diaginertia="7.89997e-07 7.89997e-07 8e-08" />
                                                    <joint name="joint_index" pos="0 0 0" axis="-1 0 0" ref="1.1" limited="true" range="0 1.51" damping="0.15"/>
                                                    <geom type="mesh" contype="0" conaffinity="0" group="1" quat="5.63312174e-04  7.06824957e-01 -5.62863772e-04  7.07388045e-01" material="grey_plastic_hand" mesh="finger_proximal" />
                                                    <geom name="index_proximal_collision" type="mesh" mesh="finger_proximal" quat="5.63312174e-04  7.06824957e-01 -5.62863772e-04  7.07388045e-01" friction="1 0.5 0.01" />

                                                    <body name="index_distal" pos="0 0.003 0.044">
                                                        <inertial pos="0.022 0 0" mass="0.01" diaginertia="7.89997e-07 7.89997e-07 8e-08" />
                                                        <joint name="joint_index_distal" pos="0 0 0" axis="1 0 0" ref="-0.5" limited="true" range="0 2" damping="0.1" />
                                                        <geom type="mesh" contype="0" conaffinity="0" group="1" quat="5.63312174e-04  7.06824957e-01 -5.62863772e-04  7.07388045e-01" material="grey_plastic_hand" mesh="finger_distal" />
                                                        <geom name="index_distal_collision" type="mesh" mesh="finger_distal" quat="5.63312174e-04  7.06824957e-01 -5.62863772e-04  7.07388045e-01" friction="1 0.5 0.01" />
                                                        <geom type="box" pos="0 0.003 0.021" quat="0.9914449 -0.1305262 0 0" size="0.01 0.005 0.02" name="index_pad_collision" solref="0.01 0.25" friction="2 0.05 0.001" />
                                                    </body>
                                                </body>

                                                <body name="pinky_proximal" pos="-0.022256 0.027073 0.114816" quat="0.96181018 -0.25771638 -0.0238668 0.08907205">
                                                    <joint name="joint_pinky" pos="0 0 0" axis="-1 0 0" ref="1.1" limited="true" range="0 1.51" damping="0.15"/>
                                                    <inertial pos="0.022 0 0" mass="0.01" diaginertia="7.89997e-07 7.89997e-07 8e-08" />
                                                    <geom type="mesh" contype="0" conaffinity="0" group="1" quat="5.63312174e-04  7.06824957e-01 -5.62863772e-04  7.07388045e-01" material="grey_plastic_hand" mesh="finger_proximal" />
                                                    <geom name="pinky_proximal_collision" type="mesh" mesh="finger_proximal" quat="5.63312174e-04  7.06824957e-01 -5.62863772e-04  7.07388045e-01" friction="1 0.5 0.01" />

                                                    <body name="pinky_distal" pos="0 0.003 0.044">
                                                        <inertial pos="0.022 0 0" mass="0.01" diaginertia="7.89997e-07 7.89997e-07 8e-08" />
                                                        <joint name="joint_pinky_distal" pos="0 0 0" axis="1 0 0" ref="-0.5" limited="true" range="0 2" damping="0.1" />
                                                        <geom type="mesh" contype="0" conaffinity="0" group="1" quat="5.63312174e-04  7.06824957e-01 -5.62863772e-04  7.07388045e-01" material="grey_plastic_hand" mesh="finger_distal" />
                                                        <geom name="pinky_distal_collision" type="mesh" mesh="finger_distal" quat="5.63312174e-04  7.06824957e-01 -5.62863772e-04  7.07388045e-01" friction="1 0.5 0.01" />
                                                        <geom type="box" pos="0 0.003 0.021" quat="0.9914449 -0.1305262 0 0" size="0.01 0.005 0.02" name="pinky_pad_collision" solref="0.01 0.25" friction="2 0.05 0.001" />
                                                    </body>
                                                </body>
                                            </body>
                                        </body>
                                    </body>
                                </body>
                            </body>
                        </body>
                    </body>
                </body>
            </body>
        </body>
    </worldbody>

    <tendon>
		<!--Middlefinger tendons-->
		<fixed name="thumb_cpl" range="-5 5" stiffness="3.0" springlength="0.2" frictionloss="0.4">
			<joint joint="joint_thumb"  coef="0.4"/>
			<joint joint="joint_thumb_distal"  coef="-0.4"/>
		</fixed>

		<!--finger2 tendons-->
        <fixed name="index_12_cpl" range="-5 5" stiffness="3.0" springlength="0.2" frictionloss="0.4">
			<joint joint="joint_index"  coef="0.4"/>
			<joint joint="joint_index_distal"  coef="-0.4"/>
		</fixed>

		<!--Finger1 tendons-->
        <fixed name="pinky_12_cpl" range="-5 5" stiffness="3.0" springlength="0.2" frictionloss="0.4">
			<joint joint="joint_pinky"  coef="0.4"/>
			<joint joint="joint_pinky_distal"  coef="-0.4"/>
		</fixed>
	</tendon>

    <equality>
		<!-- GRIPPER Couplings -->
		<tendon name="thumb_cpl" 	tendon1="thumb_cpl"/>

        <tendon name="index_12_cpl" 	tendon1="index_12_cpl"/>

        <tendon name="pinky_12_cpl" 	tendon1="pinky_12_cpl"/>
	</equality>

    <sensor>
        <force name="force_ee" site="ft_frame"/>
        <torque name="torque_ee" site="ft_frame"/>
    </sensor>

    <keyframe>
        <key time="0" qpos="3.192, 3.680, -0.000, 1.170, 0.050, 3.760, -1.510 0.5 0.0 0.5 0.0 0.5 0.0" />
    </keyframe>
</mujoco>
